<?xml version="1.0" encoding="utf-8"?>
<!-- This URDF was automatically created by SolidWorks to URDF Exporter! Originally created by Stephen Brawner (brawner@gmail.com) 
     Commit Version: 1.6.0-4-g7f85cfe  Build Version: 1.6.7995.38578
     For more information, please see http://wiki.ros.org/sw_urdf_exporter -->
<robot
  name="rover_bot">
  <link
    name="base_link">
    <inertial>
      <origin
        xyz="0.0104893096012664 -8.00198228761984E-05 -0.0357153681760934"
        rpy="0 0 0" />
      <mass
        value="6.45991309949141" />
      <inertia
        ixx="0.0300351387274575"
        ixy="2.2045257058922E-05"
        ixz="-0.00170496002630326"
        iyy="0.0672051143318267"
        iyz="-8.20582621481795E-06"
        izz="0.0889964768947195" />
    </inertial>
    <visual>
      <origin
        xyz="0 0 0"
        rpy="0 0 0" />
      <geometry>
        <mesh
          filename="package://rover_bot/meshes/base_link.STL" />
      </geometry>
      <material
        name="">
        <color
          rgba="1 1 1 1" />
      </material>
    </visual>
    <collision>
      <origin
        xyz="0 0 0"
        rpy="0 0 0" />
      <geometry>
        <mesh
          filename="package://rover_bot/meshes/base_link.STL" />
      </geometry>
    </collision>
  </link>
  <link
    name="right_f_link">
    <inertial>
      <origin
        xyz="0 0.0412058764495742 2.77555756156289E-17"
        rpy="0 0 0" />
      <mass
        value="3.83812310766081" />
      <inertia
        ixx="0.0201771651113375"
        ixy="5.31970947087293E-19"
        ixz="-0.000651438846830695"
        iyy="0.0352113922978309"
        iyz="-3.55580851430285E-19"
        izz="0.0192649208028526" />
    </inertial>
    <visual>
      <origin
        xyz="0 0 0"
        rpy="0 0 0" />
      <geometry>
        <mesh
          filename="package://rover_bot/meshes/right_f_link.STL" />
      </geometry>
      <material
        name="">
        <color
          rgba="0.792156862745098 0.819607843137255 0.933333333333333 1" />
      </material>
    </visual>
    <collision>
      <origin
        xyz="0 0 0"
        rpy="0 0 0" />
      <geometry>
        <mesh
          filename="package://rover_bot/meshes/right_f_link.STL" />
      </geometry>
    </collision>
  </link>
  <joint
    name="joint_1"
    type="continuous">
    <origin
      xyz="0.23047 -0.37087 -0.04445"
      rpy="0 0 0" />
    <parent
      link="base_link" />
    <child
      link="right_f_link" />
    <axis
      xyz="0 -1 0" />
  </joint>
  <link
    name="left_f_Link">
    <inertial>
      <origin
        xyz="-1.04083408558608E-17 0.0706428770980418 -2.77555756156289E-17"
        rpy="0 0 0" />
      <mass
        value="3.8381231076608" />
      <inertia
        ixx="0.0204409294896338"
        ixy="4.35193262552087E-19"
        ixz="-0.000337910300257584"
        iyy="0.0352113922978308"
        iyz="-1.9034995558887E-19"
        izz="0.0190011564245563" />
    </inertial>
    <visual>
      <origin
        xyz="0 0 0"
        rpy="0 0 0" />
      <geometry>
        <mesh
          filename="package://rover_bot/meshes/left_f_Link.STL" />
      </geometry>
      <material
        name="">
        <color
          rgba="0.792156862745098 0.819607843137255 0.933333333333333 1" />
      </material>
    </visual>
    <collision>
      <origin
        xyz="0 0 0"
        rpy="0 0 0" />
      <geometry>
        <mesh
          filename="package://rover_bot/meshes/left_f_Link.STL" />
      </geometry>
    </collision>
  </link>
  <joint
    name="joint_2"
    type="continuous">
    <origin
      xyz="0.23047 0.25887 -0.04445"
      rpy="0 0 0" />
    <parent
      link="base_link" />
    <child
      link="left_f_Link" />
    <axis
      xyz="0 1 0" />
  </joint>
  <link
    name="right_b_Link">
    <inertial>
      <origin
        xyz="5.55111512312578E-17 0.0412058764495742 2.77555756156289E-17"
        rpy="0 0 0" />
      <mass
        value="3.83812310766081" />
      <inertia
        ixx="0.0199129886379947"
        ixy="2.59127994265787E-18"
        ixz="0.000771736254386727"
        iyy="0.0352113922978309"
        iyz="-1.08623972730593E-18"
        izz="0.0195290972761954" />
    </inertial>
    <visual>
      <origin
        xyz="0 0 0"
        rpy="0 0 0" />
      <geometry>
        <mesh
          filename="package://rover_bot/meshes/right_b_Link.STL" />
      </geometry>
      <material
        name="">
        <color
          rgba="0.792156862745098 0.819607843137255 0.933333333333333 1" />
      </material>
    </visual>
    <collision>
      <origin
        xyz="0 0 0"
        rpy="0 0 0" />
      <geometry>
        <mesh
          filename="package://rover_bot/meshes/right_b_Link.STL" />
      </geometry>
    </collision>
  </link>
  <joint
    name="joint_3"
    type="continuous">
    <origin
      xyz="-0.21911 -0.37087 -0.04445"
      rpy="0 0 0" />
    <parent
      link="base_link" />
    <child
      link="right_b_Link" />
    <axis
      xyz="0 -1 0" />
  </joint>
  <link
    name="left_b_Link">
    <inertial>
      <origin
        xyz="0 0.0706428770980418 0"
        rpy="0 0 0" />
      <mass
        value="3.8381231076608" />
      <inertia
        ixx="0.0192036181587909"
        ixy="-2.04184943444368E-18"
        ixz="-0.000603896985297005"
        iyy="0.0352113922978308"
        iyz="1.78538638712692E-18"
        izz="0.0202384677553992" />
    </inertial>
    <visual>
      <origin
        xyz="0 0 0"
        rpy="0 0 0" />
      <geometry>
        <mesh
          filename="package://rover_bot/meshes/left_b_Link.STL" />
      </geometry>
      <material
        name="">
        <color
          rgba="0.792156862745098 0.819607843137255 0.933333333333333 1" />
      </material>
    </visual>
    <collision>
      <origin
        xyz="0 0 0"
        rpy="0 0 0" />
      <geometry>
        <mesh
          filename="package://rover_bot/meshes/left_b_Link.STL" />
      </geometry>
    </collision>
  </link>
  <joint
    name="joint_4"
    type="continuous">
    <origin
      xyz="-0.219108944993308 0.258870197777996 -0.04445"
      rpy="0 0 0" />
    <parent
      link="base_link" />
    <child
      link="left_b_Link" />
    <axis
      xyz="0 1 0" />
  </joint>
</robot>