<?xml version="1.0" encoding="utf-8"?>
<!-- This URDF was automatically created by SolidWorks to URDF Exporter! Originally created by Stephen Brawner (brawner@gmail.com) 
     Commit Version: 1.6.0-4-g7f85cfe  Build Version: 1.6.7995.38578
     For more information, please see http://wiki.ros.org/sw_urdf_exporter -->
<robot
  name="Assem2">
  <link
    name="base_link">
    <inertial>
      <origin
        xyz="0.0104893096012664 -8.00198228763094E-05 -0.0357153681760935"
        rpy="0 0 0" />
      <mass
        value="6.45991309949141" />
      <inertia
        ixx="0.0300351387274575"
        ixy="2.20452570589114E-05"
        ixz="-0.00170496002630324"
        iyy="0.0672051143318267"
        iyz="-8.20582621481869E-06"
        izz="0.0889964768947195" />
    </inertial>
    <visual>
      <origin
        xyz="0 0 0"
        rpy="0 0 0" />
      <geometry>
        <mesh
          filename="package://Assem2/meshes/base_link.STL" />
      </geometry>
      <material
        name="">
        <color
          rgba="1 1 1 1" />
      </material>
    </visual>
    <collision>
      <origin
        xyz="0 0 0"
        rpy="0 0 0" />
      <geometry>
        <mesh
          filename="package://Assem2/meshes/base_link.STL" />
      </geometry>
    </collision>
  </link>
  <link
    name="right_f_link">
    <inertial>
      <origin
        xyz="0 0.041206 0"
        rpy="0 0 0" />
      <mass
        value="3.8381" />
      <inertia
        ixx="0.020177"
        ixy="7.0643E-19"
        ixz="-0.00065144"
        iyy="0.035211"
        iyz="-3.9681E-19"
        izz="0.019265" />
    </inertial>
    <visual>
      <origin
        xyz="0 0 0"
        rpy="0 0 0" />
      <geometry>
        <mesh
          filename="package://Assem2/meshes/right_f_link.STL" />
      </geometry>
      <material
        name="">
        <color
          rgba="0.79216 0.81961 0.93333 1" />
      </material>
    </visual>
    <collision>
      <origin
        xyz="0 0 0"
        rpy="0 0 0" />
      <geometry>
        <mesh
          filename="package://Assem2/meshes/right_f_link.STL" />
      </geometry>
    </collision>
  </link>
  <joint
    name="joint_1"
    type="continuous">
    <origin
      xyz="0.23047 -0.37087 -0.04445"
      rpy="0 0 0" />
    <parent
      link="base_link" />
    <child
      link="right_f_link" />
    <axis
      xyz="0 -1 0" />
  </joint>
  <link
    name="left_f_Link">
    <inertial>
      <origin
        xyz="-1.0408E-17 0.070643 -2.7756E-17"
        rpy="0 0 0" />
      <mass
        value="3.8381" />
      <inertia
        ixx="0.020441"
        ixy="2.7255E-19"
        ixz="-0.00033791"
        iyy="0.035211"
        iyz="-2.7971E-19"
        izz="0.019001" />
    </inertial>
    <visual>
      <origin
        xyz="0 0 0"
        rpy="0 0 0" />
      <geometry>
        <mesh
          filename="package://Assem2/meshes/left_f_Link.STL" />
      </geometry>
      <material
        name="">
        <color
          rgba="0.79216 0.81961 0.93333 1" />
      </material>
    </visual>
    <collision>
      <origin
        xyz="0 0 0"
        rpy="0 0 0" />
      <geometry>
        <mesh
          filename="package://Assem2/meshes/left_f_Link.STL" />
      </geometry>
    </collision>
  </link>
  <joint
    name="joint_2"
    type="continuous">
    <origin
      xyz="0.23047 0.25887 -0.04445"
      rpy="0 0 0" />
    <parent
      link="base_link" />
    <child
      link="left_f_Link" />
    <axis
      xyz="0 1 0" />
  </joint>
  <link
    name="right_b_Link">
    <inertial>
      <origin
        xyz="0 0.0412058764495742 0"
        rpy="0 0 0" />
      <mass
        value="3.83812310766081" />
      <inertia
        ixx="0.0199129886379947"
        ixy="2.57696656795095E-18"
        ixz="0.000771736254386727"
        iyy="0.0352113922978309"
        iyz="-1.10528759304915E-18"
        izz="0.0195290972761954" />
    </inertial>
    <visual>
      <origin
        xyz="0 0 0"
        rpy="0 0 0" />
      <geometry>
        <mesh
          filename="package://Assem2/meshes/right_b_Link.STL" />
      </geometry>
      <material
        name="">
        <color
          rgba="0.792156862745098 0.819607843137255 0.933333333333333 1" />
      </material>
    </visual>
    <collision>
      <origin
        xyz="0 0 0"
        rpy="0 0 0" />
      <geometry>
        <mesh
          filename="package://Assem2/meshes/right_b_Link.STL" />
      </geometry>
    </collision>
  </link>
  <joint
    name="joint_3"
    type="continuous">
    <origin
      xyz="-0.21911 -0.37087 -0.04445"
      rpy="0 0 0" />
    <parent
      link="base_link" />
    <child
      link="right_b_Link" />
    <axis
      xyz="0 -1 0" />
  </joint>
  <link
    name="left_b_Link">
    <inertial>
      <origin
        xyz="0 0.070643 0"
        rpy="0 0 0" />
      <mass
        value="3.8381" />
      <inertia
        ixx="0.019204"
        ixy="-1.7768E-18"
        ixz="-0.0006039"
        iyy="0.035211"
        iyz="1.9541E-18"
        izz="0.020238" />
    </inertial>
    <visual>
      <origin
        xyz="0 0 0"
        rpy="0 0 0" />
      <geometry>
        <mesh
          filename="package://Assem2/meshes/left_b_Link.STL" />
      </geometry>
      <material
        name="">
        <color
          rgba="0.79216 0.81961 0.93333 1" />
      </material>
    </visual>
    <collision>
      <origin
        xyz="0 0 0"
        rpy="0 0 0" />
      <geometry>
        <mesh
          filename="package://Assem2/meshes/left_b_Link.STL" />
      </geometry>
    </collision>
  </link>
  <joint
    name="joint_4"
    type="continuous">
    <origin
      xyz="-0.21911 0.25887 -0.04445"
      rpy="0 0 0" />
    <parent
      link="base_link" />
    <child
      link="left_b_Link" />
    <axis
      xyz="0 1 0" />
  </joint>
</robot>